[2023-07-23T00:19:35.113+0000] {taskinstance.py:1103} INFO - Dependencies all met for dep_context=non-requeueable deps ti=<TaskInstance: postgres_db_dag.get_movie_data manual__2023-07-23T00:19:32.183611+00:00 [queued]>
[2023-07-23T00:19:35.124+0000] {taskinstance.py:1103} INFO - Dependencies all met for dep_context=requeueable deps ti=<TaskInstance: postgres_db_dag.get_movie_data manual__2023-07-23T00:19:32.183611+00:00 [queued]>
[2023-07-23T00:19:35.124+0000] {taskinstance.py:1308} INFO - Starting attempt 1 of 1
[2023-07-23T00:19:35.133+0000] {taskinstance.py:1327} INFO - Executing <Task(PythonOperator): get_movie_data> on 2023-07-23 00:19:32.183611+00:00
[2023-07-23T00:19:35.143+0000] {standard_task_runner.py:57} INFO - Started process 15026 to run task
[2023-07-23T00:19:35.148+0000] {standard_task_runner.py:84} INFO - Running: ['***', 'tasks', 'run', 'postgres_db_dag', 'get_movie_data', 'manual__2023-07-23T00:19:32.183611+00:00', '--job-id', '79', '--raw', '--subdir', 'DAGS_FOLDER/postgres_db_dag.py', '--cfg-path', '/tmp/tmprlzupuy9']
[2023-07-23T00:19:35.151+0000] {standard_task_runner.py:85} INFO - Job 79: Subtask get_movie_data
[2023-07-23T00:19:35.227+0000] {task_command.py:410} INFO - Running <TaskInstance: postgres_db_dag.get_movie_data manual__2023-07-23T00:19:32.183611+00:00 [running]> on host ab92f9d9cc0f
[2023-07-23T00:19:35.299+0000] {taskinstance.py:1547} INFO - Exporting env vars: AIRFLOW_CTX_DAG_OWNER='***' AIRFLOW_CTX_DAG_ID='postgres_db_dag' AIRFLOW_CTX_TASK_ID='get_movie_data' AIRFLOW_CTX_EXECUTION_DATE='2023-07-23T00:19:32.183611+00:00' AIRFLOW_CTX_TRY_NUMBER='1' AIRFLOW_CTX_DAG_RUN_ID='manual__2023-07-23T00:19:32.183611+00:00'
[2023-07-23T00:19:35.304+0000] {taskinstance.py:1824} ERROR - Task failed with exception
Traceback (most recent call last):
  File "/home/airflow/.local/lib/python3.7/site-packages/airflow/operators/python.py", line 181, in execute
    return_value = self.execute_callable()
  File "/home/airflow/.local/lib/python3.7/site-packages/airflow/operators/python.py", line 198, in execute_callable
    return self.python_callable(*self.op_args, **self.op_kwargs)
  File "/opt/airflow/dags/postgres_db_dag.py", line 13, in get_movie_data
    conn=hook.get_conn()
UnboundLocalError: local variable 'hook' referenced before assignment
[2023-07-23T00:19:35.318+0000] {taskinstance.py:1350} INFO - Marking task as FAILED. dag_id=postgres_db_dag, task_id=get_movie_data, execution_date=20230723T001932, start_date=20230723T001935, end_date=20230723T001935
[2023-07-23T00:19:35.328+0000] {standard_task_runner.py:109} ERROR - Failed to execute job 79 for task get_movie_data (local variable 'hook' referenced before assignment; 15026)
[2023-07-23T00:19:35.361+0000] {local_task_job_runner.py:225} INFO - Task exited with return code 1
[2023-07-23T00:19:35.380+0000] {taskinstance.py:2653} INFO - 0 downstream tasks scheduled from follow-on schedule check
