[2023-07-23T00:15:38.106+0000] {taskinstance.py:1103} INFO - Dependencies all met for dep_context=non-requeueable deps ti=<TaskInstance: postgres_db_dag.get_movie_data manual__2023-07-23T00:15:34.424531+00:00 [queued]>
[2023-07-23T00:15:38.121+0000] {taskinstance.py:1103} INFO - Dependencies all met for dep_context=requeueable deps ti=<TaskInstance: postgres_db_dag.get_movie_data manual__2023-07-23T00:15:34.424531+00:00 [queued]>
[2023-07-23T00:15:38.123+0000] {taskinstance.py:1308} INFO - Starting attempt 1 of 1
[2023-07-23T00:15:38.138+0000] {taskinstance.py:1327} INFO - Executing <Task(PythonOperator): get_movie_data> on 2023-07-23 00:15:34.424531+00:00
[2023-07-23T00:15:38.153+0000] {standard_task_runner.py:57} INFO - Started process 14951 to run task
[2023-07-23T00:15:38.158+0000] {standard_task_runner.py:84} INFO - Running: ['***', 'tasks', 'run', 'postgres_db_dag', 'get_movie_data', 'manual__2023-07-23T00:15:34.424531+00:00', '--job-id', '78', '--raw', '--subdir', 'DAGS_FOLDER/postgres_db_dag.py', '--cfg-path', '/tmp/tmp9n633qxb']
[2023-07-23T00:15:38.162+0000] {standard_task_runner.py:85} INFO - Job 78: Subtask get_movie_data
[2023-07-23T00:15:38.226+0000] {task_command.py:410} INFO - Running <TaskInstance: postgres_db_dag.get_movie_data manual__2023-07-23T00:15:34.424531+00:00 [running]> on host ab92f9d9cc0f
[2023-07-23T00:15:38.286+0000] {taskinstance.py:1547} INFO - Exporting env vars: AIRFLOW_CTX_DAG_OWNER='***' AIRFLOW_CTX_DAG_ID='postgres_db_dag' AIRFLOW_CTX_TASK_ID='get_movie_data' AIRFLOW_CTX_EXECUTION_DATE='2023-07-23T00:15:34.424531+00:00' AIRFLOW_CTX_TRY_NUMBER='1' AIRFLOW_CTX_DAG_RUN_ID='manual__2023-07-23T00:15:34.424531+00:00'
[2023-07-23T00:15:38.288+0000] {taskinstance.py:1824} ERROR - Task failed with exception
Traceback (most recent call last):
  File "/home/airflow/.local/lib/python3.7/site-packages/airflow/operators/python.py", line 181, in execute
    return_value = self.execute_callable()
  File "/home/airflow/.local/lib/python3.7/site-packages/airflow/operators/python.py", line 198, in execute_callable
    return self.python_callable(*self.op_args, **self.op_kwargs)
  File "/opt/airflow/dags/postgres_db_dag.py", line 13, in get_movie_data
    conn=hook.get_conn()
UnboundLocalError: local variable 'hook' referenced before assignment
[2023-07-23T00:15:38.299+0000] {taskinstance.py:1350} INFO - Marking task as FAILED. dag_id=postgres_db_dag, task_id=get_movie_data, execution_date=20230723T001534, start_date=20230723T001538, end_date=20230723T001538
[2023-07-23T00:15:38.306+0000] {standard_task_runner.py:109} ERROR - Failed to execute job 78 for task get_movie_data (local variable 'hook' referenced before assignment; 14951)
[2023-07-23T00:15:38.330+0000] {local_task_job_runner.py:225} INFO - Task exited with return code 1
[2023-07-23T00:15:38.349+0000] {taskinstance.py:2653} INFO - 0 downstream tasks scheduled from follow-on schedule check
