[2023-07-23T00:04:02.710+0000] {taskinstance.py:1103} INFO - Dependencies all met for dep_context=non-requeueable deps ti=<TaskInstance: postgres_db_dag.get_movie_data scheduled__2023-07-22T00:00:00+00:00 [queued]>
[2023-07-23T00:04:02.799+0000] {taskinstance.py:1103} INFO - Dependencies all met for dep_context=requeueable deps ti=<TaskInstance: postgres_db_dag.get_movie_data scheduled__2023-07-22T00:00:00+00:00 [queued]>
[2023-07-23T00:04:02.800+0000] {taskinstance.py:1308} INFO - Starting attempt 1 of 1
[2023-07-23T00:04:02.820+0000] {taskinstance.py:1327} INFO - Executing <Task(PythonOperator): get_movie_data> on 2023-07-22 00:00:00+00:00
[2023-07-23T00:04:02.856+0000] {standard_task_runner.py:57} INFO - Started process 14745 to run task
[2023-07-23T00:04:02.863+0000] {standard_task_runner.py:84} INFO - Running: ['***', 'tasks', 'run', 'postgres_db_dag', 'get_movie_data', 'scheduled__2023-07-22T00:00:00+00:00', '--job-id', '76', '--raw', '--subdir', 'DAGS_FOLDER/postgres_db_dag.py', '--cfg-path', '/tmp/tmpsm0xo83z']
[2023-07-23T00:04:02.870+0000] {standard_task_runner.py:85} INFO - Job 76: Subtask get_movie_data
[2023-07-23T00:04:02.954+0000] {task_command.py:410} INFO - Running <TaskInstance: postgres_db_dag.get_movie_data scheduled__2023-07-22T00:00:00+00:00 [running]> on host ab92f9d9cc0f
[2023-07-23T00:04:03.058+0000] {taskinstance.py:1547} INFO - Exporting env vars: AIRFLOW_CTX_DAG_OWNER='***' AIRFLOW_CTX_DAG_ID='postgres_db_dag' AIRFLOW_CTX_TASK_ID='get_movie_data' AIRFLOW_CTX_EXECUTION_DATE='2023-07-22T00:00:00+00:00' AIRFLOW_CTX_TRY_NUMBER='1' AIRFLOW_CTX_DAG_RUN_ID='scheduled__2023-07-22T00:00:00+00:00'
[2023-07-23T00:04:03.063+0000] {taskinstance.py:1824} ERROR - Task failed with exception
Traceback (most recent call last):
  File "/home/airflow/.local/lib/python3.7/site-packages/airflow/operators/python.py", line 181, in execute
    return_value = self.execute_callable()
  File "/home/airflow/.local/lib/python3.7/site-packages/airflow/operators/python.py", line 198, in execute_callable
    return self.python_callable(*self.op_args, **self.op_kwargs)
  File "/opt/airflow/dags/postgres_db_dag.py", line 13, in get_movie_data
    pg_conn=pg_hook.get_conn()
UnboundLocalError: local variable 'pg_hook' referenced before assignment
[2023-07-23T00:04:03.076+0000] {taskinstance.py:1350} INFO - Marking task as FAILED. dag_id=postgres_db_dag, task_id=get_movie_data, execution_date=20230722T000000, start_date=20230723T000402, end_date=20230723T000403
[2023-07-23T00:04:03.084+0000] {standard_task_runner.py:109} ERROR - Failed to execute job 76 for task get_movie_data (local variable 'pg_hook' referenced before assignment; 14745)
[2023-07-23T00:04:03.115+0000] {local_task_job_runner.py:225} INFO - Task exited with return code 1
[2023-07-23T00:04:03.134+0000] {taskinstance.py:2653} INFO - 0 downstream tasks scheduled from follow-on schedule check
